Workbook

Sheet underwriting
B1: STR INVESTMENT UNDERWRITING
B2: Address: | D2: {{address}}
C4: Assumption | D4: Low | E4: Mid | F4: High | H4: HOLDING COSTS | I4: Monthly | J4: Yearly
B5: PROPERTY INFO | H5: Internet | I5: 100 | J5: =I5*12 -> 1200
B6: Bedrooms | D6: 6 | H6: Water | I6: 0 | J6: =I6*12 -> 0
B7: Bathrooms | D7: 4 | H7: Electricity | I7: 100 | J7: =I7*12 -> 1200
B8: Square Footage | D8: 3000 | H8: Natural Gas | I8: 0 | J8: =I8*12 -> 0
B9: Market | D9: {{market}} | H9: Pest Control | I9: 13 | J9: =I9*12 -> 156
H10: Pool Maintenance | I10: 200 | J10: =I10*12 -> 2400
B11: PURCHASE DETAILS & FINANCING | H11: Outdoor / Landscaping | I11: 150 | J11: =I11*12 -> 1800
B12: Purchase Price | D12: 850000 | H12: Garbage | I12: 50 | J12: =I12*12 -> 600
B13: Down Payment | C13: 0.1 | D13: =D12*C13 -> 85000 | H13: Supplies | I13: 0 | J13: =I13*12 -> 0
B14: Loan Amount | D14: =D12-D13 -> 765000 | H14: Cleaning | I14: 0 | J14: =I14*12 -> 0
B15: Interest Rate | C15: 0.07 | H15: Property Taxes | I15: 200 | J15: =I15*12 -> 2400
B16: Loan Term (Yrs) | C16: 30 | H16: Home Insurance | I16: 250 | J16: =I16*12 -> 3000
B17: Loan Type | D17: conventional | H17: Mortgage | I17: =D20 -> 5089.5641 | J17: =I17*12 -> 61074.769
B18: Closing Costs | C18: 0.03 | D18: =D12*C18 -> 25500 | H18: Total Holding Costs | I18: =SUM(I5:I17) -> 6152.5641 | J18: =I18*12 -> 73830.769
B19: Mortgage Insurance (Annual) | C19: 0.005 | D19: =D14*C19 -> 3825
B20: Monthly Payment | D20: =IF(C15=0,D14/(C16*12),(D14*(C15/12)*(1+C15/12)^(C16*12))/((1+C15/12)^(C16*12)-1)) -> 5089.5641
B21: Annual Debt Service | D21: =D20*12 -> 61074.769
B22: Year 1 Principal Paydown | D22: =D21-D14*C15 -> 7524.7691
B24: SET UP COSTS
B25: Renovation / Amenities / Furniture | D25: 0
B26: Other | D26: 0
B27: Total Set Up | D27: =D25+D26 -> 0
B28: TOTAL CASH TO CLOSE | D28: =D13+D18+D27 -> 110500
B30: REVENUE ESTIMATE
B31: Average Daily Rate (ADR) | D31: 275 | E31: 325 | F31: 375
B32: Occupancy Rate | D32: 0.58 | E32: 0.65 | F32: 0.72
B33: Gross Annual Revenue | D33: =D31*D32*365 -> 58217.5 | E33: =E31*E32*365 -> 77106.25 | F33: =F31*F32*365 -> 98550
B34: Avg Stay (Nights) | C34: 3.5
B35: Est. Annual Turns | D35: =ROUND(365*D32/C34,0) -> 60 | E35: =ROUND(365*E32/C34,0) -> 68 | F35: =ROUND(365*F32/C34,0) -> 75
B36: Data Source / Confidence | D36: {{data_source}}
B38: OPERATING EXPENSES | C38: Assumption
B39: Platform Fees (% of revenue) | C39: 0.03 | D39: =D33*C39 -> 1746.525 | E39: =E33*C39 -> 2313.1875 | F39: =F33*C39 -> 2956.5
B40: Property Management (% of revenue) | C40: 0.2 | D40: =D33*C40 -> 11643.5 | E40: =E33*C40 -> 15421.25 | F40: =F33*C40 -> 19710
B41: Cleaning (per turn × turns, by beds) | C41: =IF(D6>=8,550,IF(D6=7,450,IF(D6=6,400,350))) -> 400 | D41: =C41*D35 -> 24000 | E41: =C41*E35 -> 27200 | F41: =C41*F35 -> 30000
B42: Supplies — Annual (by beds) | C42: =IF(D6>=8,800,IF(D6=7,700,IF(D6=6,500,400))) -> 500 | D42: =C42 -> 500 | E42: =C42 -> 500 | F42: =C42 -> 500
B43: Utilities (Monthly) | C43: 500 | D43: =C43*12 -> 6000 | E43: =C43*12 -> 6000 | F43: =C43*12 -> 6000
B44: Insurance (Annual) | C44: 3000 | D44: =C44 -> 3000 | E44: =C44 -> 3000 | F44: =C44 -> 3000
...

Sheet long_term_ROI
B1: STR LONG-TERM ROI — 10-YEAR HOLD (Mid Scenario)
B2: Address: | C2: =underwriting!D2 -> {{address}}
C4: Year 1 | D4: Year 2 | E4: Year 3 | F4: Year 4 | G4: Year 5 | H4: Year 6 | I4: Year 7 | J4: Year 8 | K4: Year 9 | L4: Year 10
B6: ASSUMPTIONS
B7: Annual Cash Flow (Mid) | C7: =underwriting!E61 -> -48877.957 | D7: =underwriting!E61 -> -48877.957 | E7: =underwriting!E61 -> -48877.957 | F7: =underwriting!E61 -> -48877.957 | G7: =underwriting!E61 -> -48877.957 | H7: =underwriting!E61 -> -48877.957 | I7: =underwriting!E61 -> -48877.957 | J7: =underwriting!E61 -> -48877.957 | K7: =underwriting!E61 -> -48877.957 | L7: =underwriting!E61 -> -48877.957
B8: Federal Tax Savings (Yr 1 bonus, then SL) | C8: =underwriting!D77 -> 22708.513 | D8: =underwriting!D74*underwriting!C76 -> 2580.5128 | E8: =underwriting!D74*underwriting!C76 -> 2580.5128 | F8: =underwriting!D74*underwriting!C76 -> 2580.5128 | G8: =underwriting!D74*underwriting!C76 -> 2580.5128 | H8: =underwriting!D74*underwriting!C76 -> 2580.5128 | I8: =underwriting!D74*underwriting!C76 -> 2580.5128 | J8: =underwriting!D74*underwriting!C76 -> 2580.5128 | K8: =underwriting!D74*underwriting!C76 -> 2580.5128 | L8: =underwriting!D74*underwriting!C76 -> 2580.5128
B9: Appreciation Rate | C9: 0
B10: Purchase Price | C10: =underwriting!D12 -> 850000
B12: CUMULATIVE RETURN COMPONENTS (Mid Scenario)
B13: Annual Cash Flow | C13: =underwriting!E61 -> -48877.957 | D13: =underwriting!E61 -> -48877.957 | E13: =underwriting!E61 -> -48877.957 | F13: =underwriting!E61 -> -48877.957 | G13: =underwriting!E61 -> -48877.957 | H13: =underwriting!E61 -> -48877.957 | I13: =underwriting!E61 -> -48877.957 | J13: =underwriting!E61 -> -48877.957 | K13: =underwriting!E61 -> -48877.957 | L13: =underwriting!E61 -> -48877.957
B14: Cumulative Cash Flow | C14: =C13 -> -48877.957 | D14: =C14+D13 -> -97755.913 | E14: =D14+E13 -> -146633.87 | F14: =E14+F13 -> -195511.83 | G14: =F14+G13 -> -244389.78 | H14: =G14+H13 -> -293267.74 | I14: =H14+I13 -> -342145.7 | J14: =I14+J13 -> -391023.65 | K14: =J14+K13 -> -439901.61 | L14: =K14+L13 -> -488779.57
B15: Annual Tax Savings | C15: =underwriting!D77 -> 22708.513 | D15: =underwriting!D74*underwriting!C76 -> 2580.5128 | E15: =underwriting!D74*underwriting!C76 -> 2580.5128 | F15: =underwriting!D74*underwriting!C76 -> 2580.5128 | G15: =underwriting!D74*underwriting!C76 -> 2580.5128 | H15: =underwriting!D74*underwriting!C76 -> 2580.5128 | I15: =underwriting!D74*underwriting!C76 -> 2580.5128 | J15: =underwriting!D74*underwriting!C76 -> 2580.5128 | K15: =underwriting!D74*underwriting!C76 -> 2580.5128 | L15: =underwriting!D74*underwriting!C76 -> 2580.5128
B16: Cumulative Tax Savings | C16: =C15 -> 22708.513 | D16: =C16+D15 -> 25289.026 | E16: =D16+E15 -> 27869.538 | F16: =E16+F15 -> 30450.051 | G16: =F16+G15 -> 33030.564 | H16: =G16+H15 -> 35611.077 | I16: =H16+I15 -> 38191.59 | J16: =I16+J15 -> 40772.103 | K16: =J16+K15 -> 43352.615 | L16: =K16+L15 -> 45933.128
B17: Annual Appreciation (0% baseline) | C17: =underwriting!D12*$C$9 -> 0 | D17: =underwriting!D12*$C$9 -> 0 | E17: =underwriting!D12*$C$9 -> 0 | F17: =underwriting!D12*$C$9 -> 0 | G17: =underwriting!D12*$C$9 -> 0 | H17: =underwriting!D12*$C$9 -> 0 | I17: =underwriting!D12*$C$9 -> 0 | J17: =underwriting!D12*$C$9 -> 0 | K17: =underwriting!D12*$C$9 -> 0 | L17: =underwriting!D12*$C$9 -> 0
B18: Cumulative Appreciation | C18: =C17 -> 0 | D18: =C18+D17 -> 0 | E18: =D18+E17 -> 0 | F18: =E18+F17 -> 0 | G18: =F18+G17 -> 0 | H18: =G18+H17 -> 0 | I18: =H18+I17 -> 0 | J18: =I18+J17 -> 0 | K18: =J18+K17 -> 0 | L18: =K18+L17 -> 0
B19: Annual Principal Paydown (approx.) | C19: =underwriting!D22 -> 7524.7691 | D19: =underwriting!D22 -> 7524.7691 | E19: =underwriting!D22 -> 7524.7691 | F19: =underwriting!D22 -> 7524.7691 | G19: =underwriting!D22 -> 7524.7691 | H19: =underwriting!D22 -> 7524.7691 | I19: =underwriting!D22 -> 7524.7691 | J19: =underwriting!D22 -> 7524.7691 | K19: =underwriting!D22 -> 7524.7691 | L19: =underwriting!D22 -> 7524.7691
B20: Cumulative Principal Paydown | C20: =C19 -> 7524.7691 | D20: =C20+D19 -> 15049.538 | E20: =D20+E19 -> 22574.307 | F20: =E20+F19 -> 30099.076 | G20: =F20+G19 -> 37623.845 | H20: =G20+H19 -> 45148.614 | I20: =H20+I19 -> 52673.383 | J20: =I20+J19 -> 60198.152 | K20: =J20+K19 -> 67722.922 | L20: =K20+L19 -> 75247.691
B22: TOTAL CUMULATIVE RETURN ($) | C22: =C14+C16+C18+C20 -> -18644.675 | D22: =D14+D16+D18+D20 -> -57417.349 | E22: =E14+E16+E18+E20 -> -96190.024 | F22: =F14+F16+F18+F20 -> -134962.7 | G22: =G14+G16+G18+G20 -> -173735.37 | H22: =H14+H16+H18+H20 -> -212508.05 | I22: =I14+I16+I18+I20 -> -251280.72 | J22: =J14+J16+J18+J20 -> -290053.4 | ... L22: =L14+L16+L18+L20 -> -367598.75
B23: TOTAL RETURN % (of Cash Invested) | C23: =C22/underwriting!D28 -> -0.16873009 | D23: =D22/underwriting!D28 -> -0.51961402 | E23: =E22/underwriting!D28 -> -0.87049796 | F23: =F22/underwriting!D28 -> -1.2213819 | G23: =G22/underwriting!D28 -> -1.5722658 | H23: =H22/underwriting!D28 -> -1.9231498 | I23: =I22/underwriting!D28 -> -2.2740337 | J23: =J22/underwriting!D28 -> -2.6249176 | K23: =K22/underwriting!D28 -> -2.9758016 | L23: =L22/underwriting!D28 -> -3.3266855
B24: Cash-on-Cash (annual, Mid) | C24: =underwriting!E63 -> -0.44233445 | D24: =underwriting!E63 -> -0.44233445 | E24: =underwriting!E63 -> -0.44233445 | F24: =underwriting!E63 -> -0.44233445 | G24: =underwriting!E63 -> -0.44233445 | H24: =underwriting!E63 -> -0.44233445 | I24: =underwriting!E63 -> -0.44233445 | J24: =underwriting!E63 -> -0.44233445 | K24: =underwriting!E63 -> -0.44233445 | L24: =underwriting!E63 -> -0.44233445

Sheet amortization
B1: MORTGAGE AMORTIZATION TABLE
B2: Loan Amount | C2: =underwriting!D14 -> 765000
B3: Interest Rate | C3: =underwriting!C15 -> 0.07
B4: Term (Years) | C4: =underwriting!C16 -> 30
B5: Monthly Payment | C5: =underwriting!D20 -> 5089.5641
B7: Month | C7: Beg. Balance | D7: Payment | E7: Interest | F7: Principal | G7: End Balance | H7: Cum. Paydown
B8: 1 | C8: =underwriting!D14 -> 765000 | D8: =underwriting!D20 -> 5089.5641 | E8: =C8*underwriting!C15/12 -> 4462.5 | F8: =D8-E8 -> 627.06409 | G8: =C8-F8 -> 764372.94 | H8: =F8 -> 627.06409
B9: 2 | C9: =G8 -> 764372.94 | D9: =underwriting!D20 -> 5089.5641 | E9: =C9*underwriting!C15/12 -> 4458.8421 | F9: =D9-E9 -> 630.72196 | G9: =C9-F9 -> 763742.21 | H9: =H8+F9 -> 1257.7861
B10: 3 | C10: =G9 -> 763742.21 | D10: =underwriting!D20 -> 5089.5641 | E10: =C10*underwriting!C15/12 -> 4455.1629 | F10: =D10-E10 -> 634.40117 | G10: =C10-F10 -> 763107.81 | H10: =H9+F10 -> 1892.1872
B11: 4 | C11: =G10 -> 763107.81 | D11: =underwriting!D20 -> 5089.5641 | E11: =C11*underwriting!C15/12 -> 4451.4622 | F11: =D11-E11 -> 638.10185 | G11: =C11-F11 -> 762469.71 | H11: =H10+F11 -> 2530.2891
B12: 5 | C12: =G11 -> 762469.71 | D12: =underwriting!D20 -> 5089.5641 | E12: =C12*underwriting!C15/12 -> 4447.74 | F12: =D12-E12 -> 641.82411 | G12: =C12-F12 -> 761827.89 | H12: =H11+F12 -> 3172.1132
B13: 6 | C13: =G12 -> 761827.89 | D13: =underwriting!D20 -> 5089.5641 | E13: =C13*underwriting!C15/12 -> 4443.996 | F13: =D13-E13 -> 645.56808 | G13: =C13-F13 -> 761182.32 | H13: =H12+F13 -> 3817.6813
B14: 7 | C14: =G13 -> 761182.32 | D14: =underwriting!D20 -> 5089.5641 | E14: =C14*underwriting!C15/12 -> 4440.2302 | F14: =D14-E14 -> 649.3339 | G14: =C14-F14 -> 760532.98 | H14: =H13+F14 -> 4467.0152
B15: 8 | C15: =G14 -> 760532.98 | D15: =underwriting!D20 -> 5089.5641 | E15: =C15*underwriting!C15/12 -> 4436.4424 | F15: =D15-E15 -> 653.12168 | G15: =C15-F15 -> 759879.86 | H15: =H14+F15 -> 5120.1368
B16: 9 | C16: =G15 -> 759879.86 | D16: =underwriting!D20 -> 5089.5641 | E16: =C16*underwriting!C15/12 -> 4432.6325 | F16: =D16-E16 -> 656.93155 | G16: =C16-F16 -> 759222.93 | H16: =H15+F16 -> 5777.0684
B17: 10 | C17: =G16 -> 759222.93 | D17: =underwriting!D20 -> 5089.5641 | E17: =C17*underwriting!C15/12 -> 4428.8004 | F17: =D17-E17 -> 660.76365 | G17: =C17-F17 -> 758562.17 | H17: =H16+F17 -> 6437.832
B18: 11 | C18: =G17 -> 758562.17 | D18: =underwriting!D20 -> 5089.5641 | E18: =C18*underwriting!C15/12 -> 4424.946 | F18: =D18-E18 -> 664.61811 | G18: =C18-F18 -> 757897.55 | H18: =H17+F18 -> 7102.4501
B19: 12 | C19: =G18 -> 757897.55 | D19: =underwriting!D20 -> 5089.5641 | E19: =C19*underwriting!C15/12 -> 4421.069 | F19: =D19-E19 -> 668.49505 | G19: =C19-F19 -> 757229.05 | H19: =H18+F19 -> 7770.9452
B20: 13 | C20: =G19 -> 757229.05 | D20: =underwriting!D20 -> 5089.5641 | E20: =C20*underwriting!C15/12 -> 4417.1695 | F20: =D20-E20 -> 672.3946 | G20: =C20-F20 -> 756556.66 | H20: =H19+F20 -> 8443.3398
B21: 14 | C21: =G20 -> 756556.66 | D21: =underwriting!D20 -> 5089.5641 | E21: =C21*underwriting!C15/12 -> 4413.2472 | F21: =D21-E21 -> 676.3169 | G21: =C21-F21 -> 755880.34 | H21: =H20+F21 -> 9119.6567
B22: 15 | C22: =G21 -> 755880.34 | D22: =underwriting!D20 -> 5089.5641 | E22: =C22*underwriting!C15/12 -> 4409.302 | F22: =D22-E22 -> 680.26209 | G22: =C22-F22 -> 755200.08 | H22: =H21+F22 -> 9799.9188
B23: 16 | C23: =G22 -> 755200.08 | D23: =underwriting!D20 -> 5089.5641 | E23: =C23*underwriting!C15/12 -> 4405.3338 | F23: =D23-E23 -> 684.23028 | G23: =C23-F23 -> 754515.85 | H23: =H22+F23 -> 10484.149
B24: 17 | C24: =G23 -> 754515.85 | D24: =underwriting!D20 -> 5089.5641 | E24: =C24*underwriting!C15/12 -> 4401.3425 | F24: =D24-E24 -> 688.22162 | G24: =C24-F24 -> 753827.63 | H24: =H23+F24 -> 11172.371
B25: 18 | C25: =G24 -> 753827.63 | D25: =underwriting!D20 -> 5089.5641 | E25: =C25*underwriting!C15/12 -> 4397.3278 | F25: =D25-E25 -> 692.23625 | G25: =C25-F25 -> 753135.39 | H25: =H24+F25 -> 11864.607
B26: 19 | C26: =G25 -> 753135.39 | D26: =underwriting!D20 -> 5089.5641 | E26: =C26*underwriting!C15/12 -> 4393.2898 | F26: =D26-E26 -> 696.2743 | G26: =C26-F26 -> 752439.12 | H26: =H25+F26 -> 12560.881
B27: 20 | C27: =G26 -> 752439.12 | D27: =underwriting!D20 -> 5089.5641 | E27: =C27*underwriting!C15/12 -> 4389.2282 | F27: =D27-E27 -> 700.3359 | G27: =C27-F27 -> 751738.78 | H27: =H26+F27 -> 13261.217
B28: 21 | C28: =G27 -> 751738.78 | D28: =underwriting!D20 -> 5089.5641 | E28: =C28*underwriting!C15/12 -> 4385.1429 | F28: =D28-E28 -> 704.42119 | G28: =C28-F28 -> 751034.36 | H28: =H27+F28 -> 13965.638
B29: 22 | C29: =G28 -> 751034.36 | D29: =underwriting!D20 -> 5089.5641 | E29: =C29*underwriting!C15/12 -> 4381.0338 | F29: =D29-E29 -> 708.53031 | G29: =C29-F29 -> 750325.83 | H29: =H28+F29 -> 14674.169
B30: 23 | C30: =G29 -> 750325.83 | D30: =underwriting!D20 -> 5089.5641 | E30: =C30*underwriting!C15/12 -> 4376.9007 | F30: =D30-E30 -> 712.66341 | G30: =C30-F30 -> 749613.17 | H30: =H29+F30 -> 15386.832
B31: 24 | C31: =G30 -> 749613.17 | D31: =underwriting!D20 -> 5089.5641 | E31: =C31*underwriting!C15/12 -> 4372.7435 | F31: =D31-E31 -> 716.82061 | G31: =C31-F31 -> 748896.35 | H31: =H30+F31 -> 16103.653
B32: 25 | C32: =G31 -> 748896.35 | D32: =underwriting!D20 -> 5089.5641 | E32: =C32*underwriting!C15/12 -> 4368.562 | F32: =D32-E32 -> 721.00206 | G32: =C32-F32 -> 748175.35 | H32: =H31+F32 -> 16824.655
B33: 26 | C33: =G32 -> 748175.35 | D33: =underwriting!D20 -> 5089.5641 | E33: =C33*underwriting!C15/12 -> 4364.3562 | F33: =D33-E33 -> 725.20791 | G33: =C33-F33 -> 747450.14 | H33: =H32+F33 -> 17549.863
B34: 27 | C34: =G33 -> 747450.14 | D34: =underwriting!D20 -> 5089.5641 | E34: =C34*underwriting!C15/12 -> 4360.1258 | F34: =D34-E34 -> 729.43829 | G34: =C34-F34 -> 746720.7 | H34: =H33+F34 -> 18279.301
B35: 28 | C35: =G34 -> 746720.7 | D35: =underwriting!D20 -> 5089.5641 | E35: =C35*underwriting!C15/12 -> 4355.8707 | F35: =D35-E35 -> 733.69334 | G35: =C35-F35 -> 745987.01 | H35: =H34+F35 -> 19012.994
B36: 29 | C36: =G35 -> 745987.01 | D36: =underwriting!D20 -> 5089.5641 | E36: =C36*underwriting!C15/12 -> 4351.5909 | F36: =D36-E36 -> 737.97322 | G36: =C36-F36 -> 745249.03 | H36: =H35+F36 -> 19750.967
B37: 30 | C37: =G36 -> 745249.03 | D37: =underwriting!D20 -> 5089.5641 | E37: =C37*underwriting!C15/12 -> 4347.286 | F37: =D37-E37 -> 742.27807 | G37: =C37-F37 -> 744506.75 | H37: =H36+F37 -> 20493.246
B38: 31 | C38: =G37 -> 744506.75 | D38: =underwriting!D20 -> 5089.5641 | E38: =C38*underwriting!C15/12 -> 4342.9561 | F38: =D38-E38 -> 746.60802 | G38: =C38-F38 -> 743760.15 | H38: =H37+F38 -> 21239.854
B39: 32 | C39: =G38 -> 743760.15 | D39: =underwriting!D20 -> 5089.5641 | E39: =C39*underwriting!C15/12 -> 4338.6009 | F39: =D39-E39 -> 750.96323 | G39: =C39-F39 -> 743009.18 | H39: =H38+F39 -> 21990.817
B40: 33 | C40: =G39 -> 743009.18 | D40: =underwriting!D20 -> 5089.5641 | E40: =C40*underwriting!C15/12 -> 4334.2202 | F40: =D40-E40 -> 755.34385 | G40: =C40-F40 -> 742253.84 | H40: =H39+F40 -> 22746.161
B41: 34 | C41: =G40 -> 742253.84 | D41: =underwriting!D20 -> 5089.5641 | E41: =C41*underwriting!C15/12 -> 4329.8141 | F41: =D41-E41 -> 759.75003 | G41: =C41-F41 -> 741494.09 | H41: =H40+F41 -> 23505.911
...
